Workbook

Sheet Gerencial
A1: conta | G1: Série Histórica Mensal
A2: Conta | C2: Descrição | D2: Selecionar Mês Referência
D3: 2026/10 | F3: 2026/10 | G3: 2026/09 | H3: 2026/08 | I3: 2026/07 | J3: 2026/06 | K3: 2026/05 | L3: 2026/04 | M3: 2026/03 | N3: 2026/02 | O3: 2026/01 | P3: 2025/12 | Q3: 2025/11 | R3: 2025/10 | S3: 2025/09 | T3: 2025/08 | U3: 2025/07 | V3: 2025/06 | W3: 2025/05 | X3: 2025/04 | Y3: 2025/03 | Z3: 2025/02 | AA3: 2025/01 | AB3: 2024/12 | AC3: 2024/11 | AD3: 2024/10 | AE3: 2024/09 | AF3: 2024/08 | AG3: 2024/07 | AH3: 2024/06 | AI3: 2024/05 | AJ3: 2024/04 | AK3: 2024/03 | AL3: 2024/02 | AM3: 2024/01 | AN3: 2023/12 | AO3: 2023/11
A4: Saldo Anterior | D4: {=_xlfn.XLOOKUP($D$3,INDIRECT("$F$3:$AZ3" ),INDIRECT("$F" & ROW() & ":" & "$AZ" & ROW()))} -> 6643.01 | F4: =G44 -> 6643.01 | G4: =H44 -> 6249.68 | H4: =I44 -> 2646.99 | I4: =J44 -> 2155.39 | J4: =K44 -> 1975.11 | K4: =L44 -> 1810.62 | L4: =M44 -> 6212.91 | M4: =N44 -> 5078.76 | ... AN4: =AO44 -> 1896.71 | AO4: 0
A6: 1 | C6: RECEITAS | D6: =_xlfn.XLOOKUP($D$3,INDIRECT("$F$3:$AZ3" ),INDIRECT("$F" & ROW() & ":" & "$AZ" & ROW())) -> 3058 | F6: =SUM(F7:F10) -> 3058 | G6: =SUM(G7:G10) -> 13458 | H6: =SUM(H7:H10) -> 17512 | I6: =SUM(I7:I10) -> 14232.85 | J6: =SUM(J7:J10) -> 14696.95 | K6: =SUM(K7:K10) -> 13463.1 | L6: =SUM(L7:L10) -> 10325.1 | M6: =SUM(M7:M10) -> 13892.15 | ... AO6: =SUM(AO7:AO10) -> 13368.55
A7: 1.1 | B7: Entradas | C7: Coletas | D7: =_xlfn.XLOOKUP($D$3,INDIRECT("$F$3:$AZ3" ),INDIRECT("$F" & ROW() & ":" & "$AZ" & ROW())) -> 3058 | F7: =Entradas!$E$1930 -> 3058 | G7: =Entradas!$E$1858 -> 7583 | H7: =Entradas!$E$1788 -> 11319 | I7: =Entradas!$E$1722 -> 8038 | J7: =Entradas!$E$1656 -> 9348 | K7: =Entradas!$E$1594 -> 10083.25 | L7: =Entradas!$E$1529 -> 10139 | M7: =Entradas!$E$1467 -> 10389.35 | N7: =Entradas!$E$1401 -> 8925 | O7: =Entradas!$E$1345 -> 7269 | P7: =Entradas!$E$1281 -> 9311 | Q7: =Entradas!$E$1218 -> 8539 | R7: =Entradas!$E$1155 -> 9451 | S7: =Entradas!$E$1084 -> 6597 | T7: =Entradas!$E$1020 -> 6496 | U7: =Entradas!$E$954 -> 5258.75 | V7: =Entradas!$E$887 -> 7662 | W7: =Entradas!$E$820 -> 7668 | X7: =Entradas!$E$754 -> 9178 | Y7: =Entradas!$E$691 -> 8676 | Z7: =Entradas!$E$650 -> 7615 | AA7: =Entradas!$E$613 -> 6989 | AB7: =Entradas!$E$571 -> 8645 | AC7: =Entradas!$E$529 -> 11075 | AD7: =Entradas!$E$487 -> 9447 | AE7: =Entradas!$E$443 -> 9665 | AF7: =Entradas!$E$403 -> 7955 | AG7: =Entradas!$E$362 -> 6677 | AH7: =Entradas!$E$321 -> 9133 | AI7: =Entradas!$E$280 -> 8933 | AJ7: =Entradas!$E$237 -> 8456 | AK7: =Entradas!$E$196 -> 12294 | AL7: =Entradas!$E$154 -> 7390 | AM7: =Entradas!$E$116 -> 8517 | AN7: =Entradas!$E$77 -> 10392.6 | AO7: =Entradas!$E$39 -> 12349
A8: 1.2 | C8: Intenções | D8: =_xlfn.XLOOKUP($D$3,INDIRECT("$F$3:$AZ3" ),INDIRECT("$F" & ROW() & ":" & "$AZ" & ROW())) -> 0 | F8: =Entradas!$K$1867 -> 0 | G8: =Entradas!$K$1797 -> 25 | H8: =Entradas!$K$1731 -> 43 | I8: =Entradas!$K$1665 -> 44.85 | J8: =Entradas!$K$1603 -> 98.95 | K8: =Entradas!$K$1538 -> 79.85 | L8: =Entradas!$K$1476 -> 186.1 | M8: =Entradas!$K$1411 -> 202.8 | N8: =Entradas!$K$1355 -> 91 | O8: =Entradas!$K$1292 -> 150.4 | P8: =Entradas!$K$1229 -> 265.45 | Q8: =Entradas!$K$1168 -> 363 | R8: =Entradas!$K$1098 -> 229.35 | S8: =Entradas!$K$1033 -> 117.3 | T8: =Entradas!$K$967 -> 62.75 | U8: =Entradas!$K$900 -> 143.4 | V8: =Entradas!$K$834 -> 40.85 | W8: =Entradas!$K$768 -> 332.35 | X8: =Entradas!$K$704 -> 257.7 | Y8: =Entradas!$K$663 -> 159.45 | Z8: =Entradas!$K$626 -> 259 | AA8: =Entradas!$K$584 -> 304.2 | AB8: =Entradas!$K$543 -> 255.35 | AC8: =Entradas!$K$501 -> 418.85 | AD8: =Entradas!$K$456 -> 257.05 | AE8: =Entradas!$K$416 -> 646.25 | AF8: =Entradas!$K$376 -> 251.85 | AG8: =Entradas!$K$336 -> 252.7 | AH8: =Entradas!$K$295 -> 382.95 | AI8: =Entradas!$K$254 -> 470.4 | AJ8: =Entradas!$K$213 -> 312.35 | AK8: =Entradas!$K$174 -> 400.2 | AL8: =Entradas!$K$141 -> 376.1 | AM8: =Entradas!$K$106 -> 367.95 | AN8: =Entradas!$K$65 -> 446.25 | AO8: =Entradas!$K$24 -> 319.55
A9: 1.3 | C9: Doações - Face | D9: =_xlfn.XLOOKUP($D$3,INDIRECT("$F$3:$AZ3" ),INDIRECT("$F" & ROW() & ":" & "$AZ" & ROW())) -> 0 | F9: =Entradas!$P$1866 -> 0 | G9: =Entradas!$P$1796 -> 5850 | H9: =Entradas!$P$1730 -> 6150 | I9: =Entradas!$P$1664 -> 6150 | J9: =Entradas!$P$1602 -> 5250 | K9: =Entradas!$P$1537 -> 3300 | L9: =Entradas!$P$1475 -> 0 | M9: =Entradas!$P$1410 -> 3300 | N9: =Entradas!$P$1354 -> 3597 | O9: =Entradas!$P$1291 -> 5150 | P9: =Entradas!$P$1228 -> 5200 | Q9: =Entradas!$P$1167 -> 5550 | R9: =Entradas!$P$1097 -> 3900 | S9: =Entradas!$P$1032 -> 8800 | T9: =Entradas!$P$966 -> 7500 | U9: =Entradas!$P$899 -> 7200 | V9: =Entradas!$P$827 -> 4200 | W9: =Entradas!$P$760 -> 4050 | X9: =Entradas!$P$697 -> 1500 | Y9: =Entradas!$P$663 -> 0 | Z9: =Entradas!$P$626 -> 0 | AA9: =Entradas!$P$584 -> 0 | AB9: =Entradas!$P$543 -> 0 | AC9: =Entradas!$P$494 -> 0 | AD9: =Entradas!$P$456 -> 0 | AE9: =Entradas!$P$416 -> 0 | AF9: =Entradas!$P$376 -> 0 | AG9: =Entradas!P336 -> 0 | AH9: =Entradas!P295 -> 0 | AI9: =Entradas!P254 -> 0 | AJ9: =Entradas!P213 -> 326.71 | AK9: =Entradas!$P$174 -> 0 | AL9: =Entradas!$P$141 -> 0 | AM9: =Entradas!$P$106 -> 200 | AN9: 0 | AO9: 0
A10: 1.4 | C10: Doações - Outras | D10: =_xlfn.XLOOKUP($D$3,INDIRECT("$F$3:$AZ3" ),INDIRECT("$F" & ROW() & ":" & "$AZ" & ROW())) -> 0 | F10: =Entradas!P1870 -> 0 | G10: =Entradas!P1800 -> 0 | H10: =Entradas!P1734 -> 0 | I10: =Entradas!P1668 -> 0 | J10: =Entradas!P1606 -> 0 | K10: =Entradas!P1541 -> 0 | L10: =Entradas!P1480 -> 0 | M10: =Entradas!P1415 -> 0 | N10: =Entradas!P1359 -> 0 | O10: =Entradas!$P$1297 -> 0 | P10: =Entradas!$P$1234 -> 150 | Q10: =Entradas!$P$1173 -> 0 | R10: =Entradas!$P$1103 -> 0 | S10: =Entradas!$P$1037 -> 0 | T10: =Entradas!$P$971 -> 0 | U10: =Entradas!$P$904 -> 0 | V10: =Entradas!$P$835 -> 406.15 | W10: =Entradas!$P$768 -> 0 | X10: =Entradas!$P$704 -> 0 | Y10: =Entradas!$P$656 -> 0 | Z10: =Entradas!$P$619 -> 0 | AA10: =Entradas!$P$577 -> 0 | AB10: =Entradas!$P$536 -> 0 | AC10: =Entradas!$P$501 -> 0 | AD10: =Entradas!$P$450 -> 0 | AE10: =Entradas!$P$410 -> 0 | AF10: =Entradas!$P$369 -> 0 | AG10: =Entradas!P328 -> 0 | AH10: =Entradas!P287 -> 0 | AI10: =Entradas!P244 -> 0 | AJ10: =Entradas!P203 -> 0 | AK10: =Entradas!$P$162 -> 0 | AL10: =Entradas!$P$86 -> 0 | AM10: =Entradas!$P$86 -> 0 | AN10: =Entradas!$P$65 -> 0 | AO10: =Entradas!$P$24 -> 700
A12: 2 | C12: DESPESAS | D12: =_xlfn.XLOOKUP($D$3,INDIRECT("$F$3:$AZ3" ),INDIRECT("$F" & ROW() & ":" & "$AZ" & ROW())) -> 4310 | F12: =SUM(F13:F17) -> 4310 | G12: =SUM(G13:G17) -> 13064.67 | H12: =SUM(H13:H17) -> 13909.31 | I12: =SUM(I13:I17) -> 13741.25 | J12: =SUM(J13:J17) -> 14516.67 | K12: =SUM(K13:K17) -> 13298.61 | L12: =SUM(L13:L17) -> 14727.39 | M12: =SUM(M13:M17) -> 12758 | ... AO12: =SUM(AO13:AO17) -> 11471.84
A13: 2.1 | B13: Outras | C13: Espórtulas | D13: =_xlfn.XLOOKUP($D$3,INDIRECT("$F$3:$AZ3" ),INDIRECT("$F" & ROW() & ":" & "$AZ" & ROW())) -> 4250 | F13: =SUMIFS(Despesas!$F:$F,Despesas!$A:$A,Gerencial!F$3,Despesas!$C:$C,Gerencial!$C13) -> 4250 | G13: =SUMIFS(Despesas!$F:$F,Despesas!$A:$A,Gerencial!G$3,Despesas!$C:$C,Gerencial!$C13) -> 12150 | H13: =SUMIFS(Despesas!$F:$F,Despesas!$A:$A,Gerencial!H$3,Despesas!$C:$C,Gerencial!$C13) -> 11800 | I13: =SUMIFS(Despesas!$F:$F,Despesas!$A:$A,Gerencial!I$3,Despesas!$C:$C,Gerencial!$C13) -> 11800 | J13: =SUMIFS(Despesas!$F:$F,Despesas!$A:$A,Gerencial!J$3,Despesas!$C:$C,Gerencial!$C13) -> 11000 | K13: =SUMIFS(Despesas!$F:$F,Despesas!$A:$A,Gerencial!K$3,Despesas!$C:$C,Gerencial!$C13) -> 11400 | L13: =SUMIFS(Despesas!$F:$F,Despesas!$A:$A,Gerencial!L$3,Despesas!$C:$C,Gerencial!$C13) -> 10350 | M13: =SUMIFS(Despesas!$F:$F,Despesas!$A:$A,Gerencial!M$3,Despesas!$C:$C,Gerencial!$C13) -> 11400 | ... AN13: =SUMIFS(Despesas!$F:$F,Despesas!$A:$A,Gerencial!AN$3,Despesas!$C:$C,Gerencial!$C13) -> 6720 | AO13: =SUMIFS(Despesas!$G$3:$G$287,Despesas!$A$3:$A$287,$AO$3,Despesas!$C$3:$C$287,$C13) -> 5310
A14: 2.2 | C14: Devolução de Empréstimos | D14: =_xlfn.XLOOKUP($D$3,INDIRECT("$F$3:$AZ3" ),INDIRECT("$F" & ROW() & ":" & "$AZ" & ROW())) -> 0 | F14: =SUMIFS(Despesas!$F:$F,Despesas!$A:$A,Gerencial!F$3,Despesas!$C:$C,Gerencial!$C14) -> 0 | G14: =SUMIFS(Despesas!$F:$F,Despesas!$A:$A,Gerencial!G$3,Despesas!$C:$C,Gerencial!$C14) -> 0 | H14: =SUMIFS(Despesas!$F:$F,Despesas!$A:$A,Gerencial!H$3,Despesas!$C:$C,Gerencial!$C14) -> 0 | I14: =SUMIFS(Despesas!$F:$F,Despesas!$A:$A,Gerencial!I$3,Despesas!$C:$C,Gerencial!$C14) -> 0 | J14: =SUMIFS(Despesas!$F:$F,Despesas!$A:$A,Gerencial!J$3,Despesas!$C:$C,Gerencial!$C14) -> 0 | K14: =SUMIFS(Despesas!$F:$F,Despesas!$A:$A,Gerencial!K$3,Despesas!$C:$C,Gerencial!$C14) -> 0 | L14: =SUMIFS(Despesas!$F:$F,Despesas!$A:$A,Gerencial!L$3,Despesas!$C:$C,Gerencial!$C14) -> 0 | M14: =SUMIFS(Despesas!$F:$F,Despesas!$A:$A,Gerencial!M$3,Despesas!$C:$C,Gerencial!$C14) -> 0 | ... AN14: =SUMIFS(Despesas!$F:$F,Despesas!$A:$A,Gerencial!AN$3,Despesas!$C:$C,Gerencial!$C14) -> 0 | AO14: =SUMIFS(Despesas!$G$3:$G$287,Despesas!$A$3:$A$287,$AO$3,Despesas!$C$3:$C$287,$C14) -> 700
A15: 2.3 | C15: Repasse AFC | D15: =_xlfn.XLOOKUP($D$3,INDIRECT("$F$3:$AZ3" ),INDIRECT("$F" & ROW() & ":" & "$AZ" & ROW())) -> 0 | F15: =SUMIFS(Despesas!$F:$F,Despesas!$A:$A,Gerencial!F$3,Despesas!$C:$C,Gerencial!$C15) -> 0 | G15: =SUMIFS(Despesas!$F:$F,Despesas!$A:$A,Gerencial!G$3,Despesas!$C:$C,Gerencial!$C15) -> 0 | H15: =SUMIFS(Despesas!$F:$F,Despesas!$A:$A,Gerencial!H$3,Despesas!$C:$C,Gerencial!$C15) -> 0 | I15: =SUMIFS(Despesas!$F:$F,Despesas!$A:$A,Gerencial!I$3,Despesas!$C:$C,Gerencial!$C15) -> 0 | J15: =SUMIFS(Despesas!$F:$F,Despesas!$A:$A,Gerencial!J$3,Despesas!$C:$C,Gerencial!$C15) -> 0 | K15: =SUMIFS(Despesas!$F:$F,Despesas!$A:$A,Gerencial!K$3,Despesas!$C:$C,Gerencial!$C15) -> 0 | L15: =SUMIFS(Despesas!$F:$F,Despesas!$A:$A,Gerencial!L$3,Despesas!$C:$C,Gerencial!$C15) -> 0 | M15: =SUMIFS(Despesas!$F:$F,Despesas!$A:$A,Gerencial!M$3,Despesas!$C:$C,Gerencial!$C15) -> 0 | ... AN15: =SUMIFS(Despesas!$F:$F,Despesas!$A:$A,Gerencial!AN$3,Despesas!$C:$C,Gerencial!$C15) -> 1000 | AO15: =SUMIFS(Despesas!$G$3:$G$287,Despesas!$A$3:$A$287,$AO$3,Despesas!$C$3:$C$287,$C15) -> 4000
A16: 2.4 | C16: Repasse Paróquia São Vicente | D16: =_xlfn.XLOOKUP($D$3,INDIRECT("$F$3:$AZ3" ),INDIRECT("$F" & ROW() & ":" & "$AZ" & ROW())) -> 0 | F16: =SUMIFS(Despesas!$F:$F,Despesas!$A:$A,Gerencial!F$3,Despesas!$C:$C,Gerencial!$C16) -> 0 | G16: =SUMIFS(Despesas!$F:$F,Despesas!$A:$A,Gerencial!G$3,Despesas!$C:$C,Gerencial!$C16) -> 0 | H16: =SUMIFS(Despesas!$F:$F,Despesas!$A:$A,Gerencial!H$3,Despesas!$C:$C,Gerencial!$C16) -> 0 | I16: =SUMIFS(Despesas!$F:$F,Despesas!$A:$A,Gerencial!I$3,Despesas!$C:$C,Gerencial!$C16) -> 0 | J16: =SUMIFS(Despesas!$F:$F,Despesas!$A:$A,Gerencial!J$3,Despesas!$C:$C,Gerencial!$C16) -> 2150 | K16: =SUMIFS(Despesas!$F:$F,Despesas!$A:$A,Gerencial!K$3,Despesas!$C:$C,Gerencial!$C16) -> 0 | L16: =SUMIFS(Despesas!$F:$F,Despesas!$A:$A,Gerencial!L$3,Despesas!$C:$C,Gerencial!$C16) -> 1965 | M16: =SUMIFS(Despesas!$F:$F,Despesas!$A:$A,Gerencial!M$3,Despesas!$C:$C,Gerencial!$C16) -> 0 | ... AN16: =SUMIFS(Despesas!$F:$F,Despesas!$A:$A,Gerencial!AN$3,Despesas!$C:$C,Gerencial!$C16) -> 625 | AO16: =SUMIFS(Despesas!$G$3:$G$287,Despesas!$A$3:$A$287,$AO$3,Despesas!$C$3:$C$287,$C16) -> 0
A17: 2.5 | C17: Itens de Consumo | D17: =_xlfn.XLOOKUP($D$3,INDIRECT("$F$3:$AZ3" ),INDIRECT("$F" & ROW() & ":" & "$AZ" & ROW())) -> 60 | F17: =SUM(F18:F40) -> 60 | G17: =SUM(G18:G40) -> 914.67 | H17: =SUM(H18:H40) -> 2109.31 | I17: =SUM(I18:I40) -> 1941.25 | J17: =SUM(J18:J40) -> 1366.67 | K17: =SUM(K18:K40) -> 1898.61 | L17: =SUM(L18:L40) -> 2412.39 | M17: =SUM(M18:M40) -> 1358 | ... AO17: =SUM(AO18:AO40) -> 1461.84
A18: 2.5.1 | B18: Itens de Consumo | C18: Decoração Capela | D18: =_xlfn.XLOOKUP($D$3,INDIRECT("$F$3:$AZ3" ),INDIRECT("$F" & ROW() & ":" & "$AZ" & ROW())) -> 0 | F18: =SUMIFS(Despesas!$F:$F,Despesas!$A:$A,Gerencial!F$3,Despesas!$C:$C,Gerencial!$C18) -> 0 | G18: =SUMIFS(Despesas!$F:$F,Despesas!$A:$A,Gerencial!G$3,Despesas!$C:$C,Gerencial!$C18) -> 0 | H18: =SUMIFS(Despesas!$F:$F,Despesas!$A:$A,Gerencial!H$3,Despesas!$C:$C,Gerencial!$C18) -> 29.99 | I18: =SUMIFS(Despesas!$F:$F,Despesas!$A:$A,Gerencial!I$3,Despesas!$C:$C,Gerencial!$C18) -> 386 | J18: =SUMIFS(Despesas!$F:$F,Despesas!$A:$A,Gerencial!J$3,Despesas!$C:$C,Gerencial!$C18) -> 563.05 | K18: =SUMIFS(Despesas!$F:$F,Despesas!$A:$A,Gerencial!K$3,Despesas!$C:$C,Gerencial!$C18) -> 0 | L18: =SUMIFS(Despesas!$F:$F,Despesas!$A:$A,Gerencial!L$3,Despesas!$C:$C,Gerencial!$C18) -> 0 | M18: =SUMIFS(Despesas!$F:$F,Despesas!$A:$A,Gerencial!M$3,Despesas!$C:$C,Gerencial!$C18) -> 194.75 | ... AN18: =SUMIFS(Despesas!$F:$F,Despesas!$A:$A,Gerencial!AN$3,Despesas!$C:$C,Gerencial!$C18) -> 163.4 | AO18: =SUMIFS(Despesas!$G$3:$G$287,Despesas!$A$3:$A$287,$AO$3,Despesas!$C$3:$C$287,$C18) -> 119.9
A19: 2.5.2 | C19: Vinho | D19: =_xlfn.XLOOKUP($D$3,INDIRECT("$F$3:$AZ3" ),INDIRECT("$F" & ROW() & ":" & "$AZ" & ROW())) -> 0 | F19: =SUMIFS(Despesas!$F:$F,Despesas!$A:$A,Gerencial!F$3,Despesas!$C:$C,Gerencial!$C19) -> 0 | G19: =SUMIFS(Despesas!$F:$F,Despesas!$A:$A,Gerencial!G$3,Despesas!$C:$C,Gerencial!$C19) -> 0 | H19: =SUMIFS(Despesas!$F:$F,Despesas!$A:$A,Gerencial!H$3,Despesas!$C:$C,Gerencial!$C19) -> 269.4 | I19: =SUMIFS(Despesas!$F:$F,Despesas!$A:$A,Gerencial!I$3,Despesas!$C:$C,Gerencial!$C19) -> 0 | J19: =SUMIFS(Despesas!$F:$F,Despesas!$A:$A,Gerencial!J$3,Despesas!$C:$C,Gerencial!$C19) -> 0 | K19: =SUMIFS(Despesas!$F:$F,Despesas!$A:$A,Gerencial!K$3,Despesas!$C:$C,Gerencial!$C19) -> 264 | L19: =SUMIFS(Despesas!$F:$F,Despesas!$A:$A,Gerencial!L$3,Despesas!$C:$C,Gerencial!$C19) -> 0 | M19: =SUMIFS(Despesas!$F:$F,Despesas!$A:$A,Gerencial!M$3,Despesas!$C:$C,Gerencial!$C19) -> 0 | ... AN19: =SUMIFS(Despesas!$F:$F,Despesas!$A:$A,Gerencial!AN$3,Despesas!$C:$C,Gerencial!$C19) -> 0 | AO19: =SUMIFS(Despesas!$G$3:$G$287,Despesas!$A$3:$A$287,$AO$3,Despesas!$C$3:C$287,$C19) -> 0
A20: 2.5.3 | C20: Partículas | D20: =_xlfn.XLOOKUP($D$3,INDIRECT("$F$3:$AZ3" ),INDIRECT("$F" & ROW() & ":" & "$AZ" & ROW())) -> 0 | F20: =SUMIFS(Despesas!$F:$F,Despesas!$A:$A,Gerencial!F$3,Despesas!$C:$C,Gerencial!$C20) -> 0 | G20: =SUMIFS(Despesas!$F:$F,Despesas!$A:$A,Gerencial!G$3,Despesas!$C:$C,Gerencial!$C20) -> 320 | H20: =SUMIFS(Despesas!$F:$F,Despesas!$A:$A,Gerencial!H$3,Despesas!$C:$C,Gerencial!$C20) -> 703 | I20: =SUMIFS(Despesas!$F:$F,Despesas!$A:$A,Gerencial!I$3,Despesas!$C:$C,Gerencial!$C20) -> 511 | J20: =SUMIFS(Despesas!$F:$F,Despesas!$A:$A,Gerencial!J$3,Despesas!$C:$C,Gerencial!$C20) -> 472.9 | K20: =SUMIFS(Despesas!$F:$F,Despesas!$A:$A,Gerencial!K$3,Despesas!$C:$C,Gerencial!$C20) -> 400 | L20: =SUMIFS(Despesas!$F:$F,Despesas!$A:$A,Gerencial!L$3,Despesas!$C:$C,Gerencial!$C20) -> 280 | M20: =SUMIFS(Despesas!$F:$F,Despesas!$A:$A,Gerencial!M$3,Despesas!$C:$C,Gerencial!$C20) -> 619.6 | ... AN20: =SUMIFS(Despesas!$F:$F,Despesas!$A:$A,Gerencial!AN$3,Despesas!$C:$C,Gerencial!$C20) -> 269 | AO20: =SUMIFS(Despesas!$G$3:$G$287,Despesas!$A$3:$A$287,$AO$3,Despesas!$C$3:C$287,$C20) -> 245
A21: 2.5.4 | C21: Água | D21: =_xlfn.XLOOKUP($D$3,INDIRECT("$F$3:$AZ3" ),INDIRECT("$F" & ROW() & ":" & "$AZ" & ROW())) -> 0 | F21: =SUMIFS(Despesas!$F:$F,Despesas!$A:$A,Gerencial!F$3,Despesas!$C:$C,Gerencial!$C21) -> 0 | G21: =SUMIFS(Despesas!$F:$F,Despesas!$A:$A,Gerencial!G$3,Despesas!$C:$C,Gerencial!$C21) -> 102 | H21: =SUMIFS(Despesas!$F:$F,Despesas!$A:$A,Gerencial!H$3,Despesas!$C:$C,Gerencial!$C21) -> 51 | I21: =SUMIFS(Despesas!$F:$F,Despesas!$A:$A,Gerencial!I$3,Despesas!$C:$C,Gerencial!$C21) -> 85 | J21: =SUMIFS(Despesas!$F:$F,Despesas!$A:$A,Gerencial!J$3,Despesas!$C:$C,Gerencial!$C21) -> 99 | K21: =SUMIFS(Despesas!$F:$F,Despesas!$A:$A,Gerencial!K$3,Despesas!$C:$C,Gerencial!$C21) -> 62 | L21: =SUMIFS(Despesas!$F:$F,Despesas!$A:$A,Gerencial!L$3,Despesas!$C:$C,Gerencial!$C21) -> 90 | M21: =SUMIFS(Despesas!$F:$F,Despesas!$A:$A,Gerencial!M$3,Despesas!$C:$C,Gerencial!$C21) -> 30 | ... AN21: =SUMIFS(Despesas!$F:$F,Despesas!$A:$A,Gerencial!AN$3,Despesas!$C:$C,Gerencial!$C21) -> 48 | AO21: =SUMIFS(Despesas!$G$3:$G$287,Despesas!$A$3:$A$287,$AO$3,Despesas!$C$3:C$287,$C21) -> 12
A22: 2.5.5 | C22: Descartáveis (Copos, pratos) | D22: =_xlfn.XLOOKUP($D$3,INDIRECT("$F$3:$AZ3" ),INDIRECT("$F" & ROW() & ":" & "$AZ" & ROW())) -> 60 | F22: =SUMIFS(Despesas!$F:$F,Despesas!$A:$A,Gerencial!F$3,Despesas!$C:$C,Gerencial!$C22) -> 60 | G22: =SUMIFS(Despesas!$F:$F,Despesas!$A:$A,Gerencial!G$3,Despesas!$C:$C,Gerencial!$C22) -> 0 | H22: =SUMIFS(Despesas!$F:$F,Despesas!$A:$A,Gerencial!H$3,Despesas!$C:$C,Gerencial!$C22) -> 306.42 | I22: =SUMIFS(Despesas!$F:$F,Despesas!$A:$A,Gerencial!I$3,Despesas!$C:$C,Gerencial!$C22) -> 0 | J22: =SUMIFS(Despesas!$F:$F,Despesas!$A:$A,Gerencial!J$3,Despesas!$C:$C,Gerencial!$C22) -> 0 | K22: =SUMIFS(Despesas!$F:$F,Despesas!$A:$A,Gerencial!K$3,Despesas!$C:$C,Gerencial!$C22) -> 0 | L22: =SUMIFS(Despesas!$F:$F,Despesas!$A:$A,Gerencial!L$3,Despesas!$C:$C,Gerencial!$C22) -> 0 | M22: =SUMIFS(Despesas!$F:$F,Despesas!$A:$A,Gerencial!M$3,Despesas!$C:$C,Gerencial!$C22) -> 0 | ... AN22: =SUMIFS(Despesas!$F:$F,Despesas!$A:$A,Gerencial!AN$3,Despesas!$C:$C,Gerencial!$C22) -> 0 | AO22: =SUMIFS(Despesas!$G$3:$G$287,Despesas!$A$3:$A$287,$AO$3,Despesas!$C$3:C$287,$C22) -> 125.94
A23: 2.5.6 | C23: Papel toalha | D23: =_xlfn.XLOOKUP($D$3,INDIRECT("$F$3:$AZ3" ),INDIRECT("$F" & ROW() & ":" & "$AZ" & ROW())) -> 0 | F23: =SUMIFS(Despesas!$F:$F,Despesas!$A:$A,Gerencial!F$3,Despesas!$C:$C,Gerencial!$C23) -> 0 | G23: =SUMIFS(Despesas!$F:$F,Despesas!$A:$A,Gerencial!G$3,Despesas!$C:$C,Gerencial!$C23) -> 33.52 | H23: =SUMIFS(Despesas!$F:$F,Despesas!$A:$A,Gerencial!H$3,Despesas!$C:$C,Gerencial!$C23) -> 37.45 | I23: =SUMIFS(Despesas!$F:$F,Despesas!$A:$A,Gerencial!I$3,Despesas!$C:$C,Gerencial!$C23) -> 55.05 | J23: =SUMIFS(Despesas!$F:$F,Despesas!$A:$A,Gerencial!J$3,Despesas!$C:$C,Gerencial!$C23) -> 0 | K23: =SUMIFS(Despesas!$F:$F,Despesas!$A:$A,Gerencial!K$3,Despesas!$C:$C,Gerencial!$C23) -> 0 | L23: =SUMIFS(Despesas!$F:$F,Despesas!$A:$A,Gerencial!L$3,Despesas!$C:$C,Gerencial!$C23) -> 0 | M23: =SUMIFS(Despesas!$F:$F,Despesas!$A:$A,Gerencial!M$3,Despesas!$C:$C,Gerencial!$C23) -> 13.58 | ... AN23: =SUMIFS(Despesas!$F:$F,Despesas!$A:$A,Gerencial!AN$3,Despesas!$C:$C,Gerencial!$C23) -> 19.73 | AO23: =SUMIFS(Despesas!$G$3:$G$287,Despesas!$A$3:$A$287,$AO$3,Despesas!$C$3:C$287,$C23) -> 21.46
A24: 2.5.7 | C24: Cheirinho ( anti-môfo) | D24: =_xlfn.XLOOKUP($D$3,INDIRECT("$F$3:$AZ3" ),INDIRECT("$F" & ROW() & ":" & "$AZ" & ROW())) -> 0 | F24: =SUMIFS(Despesas!$F:$F,Despesas!$A:$A,Gerencial!F$3,Despesas!$C:$C,Gerencial!$C24) -> 0 | G24: =SUMIFS(Despesas!$F:$F,Despesas!$A:$A,Gerencial!G$3,Despesas!$C:$C,Gerencial!$C24) -> 0 | H24: =SUMIFS(Despesas!$F:$F,Despesas!$A:$A,Gerencial!H$3,Despesas!$C:$C,Gerencial!$C24) -> 0 | I24: =SUMIFS(Despesas!$F:$F,Despesas!$A:$A,Gerencial!I$3,Despesas!$C:$C,Gerencial!$C24) -> 0 | J24: =SUMIFS(Despesas!$F:$F,Despesas!$A:$A,Gerencial!J$3,Despesas!$C:$C,Gerencial!$C24) -> 0 | K24: =SUMIFS(Despesas!$F:$F,Despesas!$A:$A,Gerencial!K$3,Despesas!$C:$C,Gerencial!$C24) -> 0 | L24: =SUMIFS(Despesas!$F:$F,Despesas!$A:$A,Gerencial!L$3,Despesas!$C:$C,Gerencial!$C24) -> 0 | M24: =SUMIFS(Despesas!$F:$F,Despesas!$A:$A,Gerencial!M$3,Despesas!$C:$C,Gerencial!$C24) -> 0 | ... AN24: =SUMIFS(Despesas!$F:$F,Despesas!$A:$A,Gerencial!AN$3,Despesas!$C:$C,Gerencial!$C24) -> 0 | AO24: =SUMIFS(Despesas!$G$3:$G$287,Despesas!$A$3:$A$287,$AO$3,Despesas!$C$3:C$287,$C24) -> 0
A25: 2.5.8 | C25: Incenso | D25: =_xlfn.XLOOKUP($D$3,INDIRECT("$F$3:$AZ3" ),INDIRECT("$F" & ROW() & ":" & "$AZ" & ROW())) -> 0 | F25: =SUMIFS(Despesas!$F:$F,Despesas!$A:$A,Gerencial!F$3,Despesas!$C:$C,Gerencial!$C25) -> 0 | G25: =SUMIFS(Despesas!$F:$F,Despesas!$A:$A,Gerencial!G$3,Despesas!$C:$C,Gerencial!$C25) -> 0 | H25: =SUMIFS(Despesas!$F:$F,Despesas!$A:$A,Gerencial!H$3,Despesas!$C:$C,Gerencial!$C25) -> 0 | I25: =SUMIFS(Despesas!$F:$F,Despesas!$A:$A,Gerencial!I$3,Despesas!$C:$C,Gerencial!$C25) -> 51.6 | J25: =SUMIFS(Despesas!$F:$F,Despesas!$A:$A,Gerencial!J$3,Despesas!$C:$C,Gerencial!$C25) -> 0 | K25: =SUMIFS(Despesas!$F:$F,Despesas!$A:$A,Gerencial!K$3,Despesas!$C:$C,Gerencial!$C25) -> 0 | L25: =SUMIFS(Despesas!$F:$F,Despesas!$A:$A,Gerencial!L$3,Despesas!$C:$C,Gerencial!$C25) -> 0 | M25: =SUMIFS(Despesas!$F:$F,Despesas!$A:$A,Gerencial!M$3,Despesas!$C:$C,Gerencial!$C25) -> 0 | ... AN25: =SUMIFS(Despesas!$F:$F,Despesas!$A:$A,Gerencial!AN$3,Despesas!$C:$C,Gerencial!$C25) -> 0 | AO25: =SUMIFS(Despesas!$G$3:$G$287,Despesas!$A$3:$A$287,$AO$3,Despesas!$C$3:C$287,$C25) -> 0
A26: 2.5.9 | C26: Carvão Tablete | D26: =_xlfn.XLOOKUP($D$3,INDIRECT("$F$3:$AZ3" ),INDIRECT("$F" & ROW() & ":" & "$AZ" & ROW())) -> 0 | F26: =SUMIFS(Despesas!$F:$F,Despesas!$A:$A,Gerencial!F$3,Despesas!$C:$C,Gerencial!$C26) -> 0 | G26: =SUMIFS(Despesas!$F:$F,Despesas!$A:$A,Gerencial!G$3,Despesas!$C:$C,Gerencial!$C26) -> 0 | H26: =SUMIFS(Despesas!$F:$F,Despesas!$A:$A,Gerencial!H$3,Despesas!$C:$C,Gerencial!$C26) -> 14.99 | I26: =SUMIFS(Despesas!$F:$F,Despesas!$A:$A,Gerencial!I$3,Despesas!$C:$C,Gerencial!$C26) -> 46.5 | J26: =SUMIFS(Despesas!$F:$F,Despesas!$A:$A,Gerencial!J$3,Despesas!$C:$C,Gerencial!$C26) -> 0 | K26: =SUMIFS(Despesas!$F:$F,Despesas!$A:$A,Gerencial!K$3,Despesas!$C:$C,Gerencial!$C26) -> 16.79 | L26: =SUMIFS(Despesas!$F:$F,Despesas!$A:$A,Gerencial!L$3,Despesas!$C:$C,Gerencial!$C26) -> 0 | M26: =SUMIFS(Despesas!$F:$F,Despesas!$A:$A,Gerencial!M$3,Despesas!$C:$C,Gerencial!$C26) -> 0 | ... AN26: =SUMIFS(Despesas!$F:$F,Despesas!$A:$A,Gerencial!AN$3,Despesas!$C:$C,Gerencial!$C26) -> 0 | AO26: =SUMIFS(Despesas!$G$3:$G$287,Despesas!$A$3:$A$287,$AO$3,Despesas!$C$3:C$287,$C26) -> 30
A27: 2.5.10 | C27: Velas ( Altar, Santíssimo e diárias ) | D27: =_xlfn.XLOOKUP($D$3,INDIRECT("$F$3:$AZ3" ),INDIRECT("$F" & ROW() & ":" & "$AZ" & ROW())) -> 0 | F27: =SUMIFS(Despesas!$F:$F,Despesas!$A:$A,Gerencial!F$3,Despesas!$C:$C,Gerencial!$C27) -> 0 | G27: =SUMIFS(Despesas!$F:$F,Despesas!$A:$A,Gerencial!G$3,Despesas!$C:$C,Gerencial!$C27) -> 272.25 | H27: =SUMIFS(Despesas!$F:$F,Despesas!$A:$A,Gerencial!H$3,Despesas!$C:$C,Gerencial!$C27) -> 0 | I27: =SUMIFS(Despesas!$F:$F,Despesas!$A:$A,Gerencial!I$3,Despesas!$C:$C,Gerencial!$C27) -> 0 | J27: =SUMIFS(Despesas!$F:$F,Despesas!$A:$A,Gerencial!J$3,Despesas!$C:$C,Gerencial!$C27) -> 0 | K27: =SUMIFS(Despesas!$F:$F,Despesas!$A:$A,Gerencial!K$3,Despesas!$C:$C,Gerencial!$C27) -> 0 | L27: =SUMIFS(Despesas!$F:$F,Despesas!$A:$A,Gerencial!L$3,Despesas!$C:$C,Gerencial!$C27) -> 0 | M27: =SUMIFS(Despesas!$F:$F,Despesas!$A:$A,Gerencial!M$3,Despesas!$C:$C,Gerencial!$C27) -> 340.4 | ... AN27: =SUMIFS(Despesas!$F:$F,Despesas!$A:$A,Gerencial!AN$3,Despesas!$C:$C,Gerencial!$C27) -> 98.7 | AO27: =SUMIFS(Despesas!$G$3:$G$287,Despesas!$A$3:$A$287,$AO$3,Despesas!$C$3:C$287,$C27) -> 319.83
A28: 2.5.11 | C28: Mangas vidro | D28: =_xlfn.XLOOKUP($D$3,INDIRECT("$F$3:$AZ3" ),INDIRECT("$F" & ROW() & ":" & "$AZ" & ROW())) -> 0 | F28: =SUMIFS(Despesas!$F:$F,Despesas!$A:$A,Gerencial!F$3,Despesas!$C:$C,Gerencial!$C28) -> 0 | G28: =SUMIFS(Despesas!$F:$F,Despesas!$A:$A,Gerencial!G$3,Despesas!$C:$C,Gerencial!$C28) -> 0 | H28: =SUMIFS(Despesas!$F:$F,Despesas!$A:$A,Gerencial!H$3,Despesas!$C:$C,Gerencial!$C28) -> 0 | I28: =SUMIFS(Despesas!$F:$F,Despesas!$A:$A,Gerencial!I$3,Despesas!$C:$C,Gerencial!$C28) -> 0 | J28: =SUMIFS(Despesas!$F:$F,Despesas!$A:$A,Gerencial!J$3,Despesas!$C:$C,Gerencial!$C28) -> 0 | K28: =SUMIFS(Despesas!$F:$F,Despesas!$A:$A,Gerencial!K$3,Despesas!$C:$C,Gerencial!$C28) -> 0 | L28: =SUMIFS(Despesas!$F:$F,Despesas!$A:$A,Gerencial!L$3,Despesas!$C:$C,Gerencial!$C28) -> 0 | M28: =SUMIFS(Despesas!$F:$F,Despesas!$A:$A,Gerencial!M$3,Despesas!$C:$C,Gerencial!$C28) -> 0 | ... AN28: =SUMIFS(Despesas!$F:$F,Despesas!$A:$A,Gerencial!AN$3,Despesas!$C:$C,Gerencial!$C28) -> 0 | AO28: =SUMIFS(Despesas!$G$3:$G$287,Despesas!$A$3:$A$287,$AO$3,Despesas!$C$3:C$287,$C28) -> 0
A29: 2.5.12 | C29: Lavanderia | D29: =_xlfn.XLOOKUP($D$3,INDIRECT("$F$3:$AZ3" ),INDIRECT("$F" & ROW() & ":" & "$AZ" & ROW())) -> 0 | F29: =SUMIFS(Despesas!$F:$F,Despesas!$A:$A,Gerencial!F$3,Despesas!$C:$C,Gerencial!$C29) -> 0 | G29: =SUMIFS(Despesas!$F:$F,Despesas!$A:$A,Gerencial!G$3,Despesas!$C:$C,Gerencial!$C29) -> 151 | H29: =SUMIFS(Despesas!$F:$F,Despesas!$A:$A,Gerencial!H$3,Despesas!$C:$C,Gerencial!$C29) -> 511.51 | I29: =SUMIFS(Despesas!$F:$F,Despesas!$A:$A,Gerencial!I$3,Despesas!$C:$C,Gerencial!$C29) -> 233.11 | J29: =SUMIFS(Despesas!$F:$F,Despesas!$A:$A,Gerencial!J$3,Despesas!$C:$C,Gerencial!$C29) -> 231.72 | K29: =SUMIFS(Despesas!$F:$F,Despesas!$A:$A,Gerencial!K$3,Despesas!$C:$C,Gerencial!$C29) -> 0 | L29: =SUMIFS(Despesas!$F:$F,Despesas!$A:$A,Gerencial!L$3,Despesas!$C:$C,Gerencial!$C29) -> 372.3 | M29: =SUMIFS(Despesas!$F:$F,Despesas!$A:$A,Gerencial!M$3,Despesas!$C:$C,Gerencial!$C29) -> 123 | ... AN29: =SUMIFS(Despesas!$F:$F,Despesas!$A:$A,Gerencial!AN$3,Despesas!$C:$C,Gerencial!$C29) -> 457.87 | AO29: =SUMIFS(Despesas!$G$3:$G$287,Despesas!$A$3:$A$287,$AO$3,Despesas!$C$3:C$287,$C29) -> 387.23
A30: 2.5.13 | C30: Alfaias litúrgicas ( corporal e sanguíneo ) | D30: =_xlfn.XLOOKUP($D$3,INDIRECT("$F$3:$AZ3" ),INDIRECT("$F" & ROW() & ":" & "$AZ" & ROW())) -> 0 | F30: =SUMIFS(Despesas!$F:$F,Despesas!$A:$A,Gerencial!F$3,Despesas!$C:$C,Gerencial!$C30) -> 0 | G30: =SUMIFS(Despesas!$F:$F,Despesas!$A:$A,Gerencial!G$3,Despesas!$C:$C,Gerencial!$C30) -> 0 | H30: =SUMIFS(Despesas!$F:$F,Despesas!$A:$A,Gerencial!H$3,Despesas!$C:$C,Gerencial!$C30) -> 0 | I30: =SUMIFS(Despesas!$F:$F,Despesas!$A:$A,Gerencial!I$3,Despesas!$C:$C,Gerencial!$C30) -> 563.2 | J30: =SUMIFS(Despesas!$F:$F,Despesas!$A:$A,Gerencial!J$3,Despesas!$C:$C,Gerencial!$C30) -> 0 | K30: =SUMIFS(Despesas!$F:$F,Despesas!$A:$A,Gerencial!K$3,Despesas!$C:$C,Gerencial!$C30) -> 0 | L30: =SUMIFS(Despesas!$F:$F,Despesas!$A:$A,Gerencial!L$3,Despesas!$C:$C,Gerencial!$C30) -> 0 | M30: =SUMIFS(Despesas!$F:$F,Despesas!$A:$A,Gerencial!M$3,Despesas!$C:$C,Gerencial!$C30) -> 0 | ... AN30: =SUMIFS(Despesas!$F:$F,Despesas!$A:$A,Gerencial!AN$3,Despesas!$C:$C,Gerencial!$C30) -> 0 | AO30: =SUMIFS(Despesas!$G$3:$G$287,Despesas!$A$3:$A$287,$AO$3,Despesas!$C$3:C$287,$C30) -> 0
... A40: 2.5.23 | C40: Livro Diretório | D40: =_xlfn.XLOOKUP($D$3,INDIRECT("$F$3:$AZ3" ),INDIRECT("$F" & ROW() & ":" & "$AZ" & ROW())) -> 0 | F40: =SUMIFS(Despesas!$F:$F,Despesas!$A:$A,Gerencial!F$3,Despesas!$C:$C,Gerencial!$C40) -> 0 | G40: =SUMIFS(Despesas!$F:$F,Despesas!$A:$A,Gerencial!G$3,Despesas!$C:$C,Gerencial!$C40) -> 0 | H40: =SUMIFS(Despesas!$F:$F,Despesas!$A:$A,Gerencial!H$3,Despesas!$C:$C,Gerencial!$C40) -> 0 | I40: =SUMIFS(Despesas!$F:$F,Despesas!$A:$A,Gerencial!I$3,Despesas!$C:$C,Gerencial!$C40) -> 0 | J40: =SUMIFS(Despesas!$F:$F,Despesas!$A:$A,Gerencial!J$3,Despesas!$C:$C,Gerencial!$C40) -> 0 | K40: =SUMIFS(Despesas!$F:$F,Despesas!$A:$A,Gerencial!K$3,Despesas!$C:$C,Gerencial!$C40) -> 0 | L40: =SUMIFS(Despesas!$F:$F,Despesas!$A:$A,Gerencial!L$3,Despesas!$C:$C,Gerencial!$C40) -> 0 | M40: =SUMIFS(Despesas!$F:$F,Despesas!$A:$A,Gerencial!M$3,Despesas!$C:$C,Gerencial!$C40) -> 0 | ... AN40: =SUMIFS(Despesas!$F:$F,Despesas!$A:$A,Gerencial!AN$3,Despesas!$C:$C,Gerencial!$C40) -> 0 | AO40: =SUMIFS(Despesas!$G$3:$G$287,Despesas!$A$3:$A$287,$AO$3,Despesas!$C$3:C$287,$C40) -> 42.5
A42: Saldo Operacional (Receitas - Despesas) | D42: =_xlfn.XLOOKUP($D$3,INDIRECT("$F$3:$AZ3" ),INDIRECT("$F" & ROW() & ":" & "$AZ" & ROW())) -> 5391.01 | F42: =F$4+F$6-F$12 -> 5391.01 | G42: =G$4+G$6-G$12 -> 6643.01 | H42: =H$4+H$6-H$12 -> 6249.68 | I42: =I$4+I$6-I$12 -> 2646.99 | J42: =J$4+J$6-J$12 -> 2155.39 | K42: =K$4+K$6-K$12 -> 1975.11 | L42: =L$4+L$6-L$12 -> 1810.62 | M42: =M$4+M$6-M$12 -> 6212.91 | ... AO42: =AO$4+AO$6-AO$12 -> 1896.71
A43: Compromissos A Pagar (Sacerdotes) | D43: =_xlfn.XLOOKUP($D$3,INDIRECT("$F$3:$AZ3" ),INDIRECT("$F" & ROW() & ":" & "$AZ" & ROW())) -> 11550 | F43: =Sacerdotes!$Q$2110 -> 11550 | G43: =Sacerdotes!$Q$2030 -> 0 | H43: =Sacerdotes!$Q$1955 -> 0 | I43: =Sacerdotes!$Q$1879 -> 0 | J43: =Sacerdotes!$Q$1802 -> 0 | K43: =Sacerdotes!$Q$1727 -> 0 | L43: =Sacerdotes!$Q$1659 -> 0 | M43: =Sacerdotes!$Q$1585 -> 0 | N43: =Sacerdotes!$Q$1520 -> 0 | O43: =Sacerdotes!$Q$1448 -> 0 | P43: =Sacerdotes!$Q$1375 -> 0 | Q43: =Sacerdotes!$Q$1305 -> 0 | R43: =Sacerdotes!$Q$1228 -> 0 | S43: =Sacerdotes!$Q$1156 -> 0 | T43: =Sacerdotes!$Q$1084 -> 0 | U43: =Sacerdotes!$Q$1011 -> 0 | V43: =Sacerdotes!$Q$941 -> 0 | W43: =Sacerdotes!$Q$869 -> 0 | X43: =Sacerdotes!$Q$800 -> 0 | Y43: =Sacerdotes!$Q$754 -> 0 | Z43: =Sacerdotes!$Q$711 -> 0 | AA43: =Sacerdotes!$Q$665 -> 0 | AB43: =Sacerdotes!$Q$618 -> 0 | AC43: =Sacerdotes!$Q$571 -> 0 | AD43: =Sacerdotes!$Q$521 -> 0 | AE43: =Sacerdotes!$Q$475 -> 0 | AF43: =Sacerdotes!$Q$428 -> 0 | AG43: =Sacerdotes!Q381 -> 0 | AH43: =Sacerdotes!Q335 -> 0 | AI43: =Sacerdotes!Q287 -> 0 | AJ43: =Sacerdotes!Q241 -> 0 | AK43: =Sacerdotes!Q200 -> 0 | AL43: =Sacerdotes!Q160 -> 0 | AM43: =SUMIFS(Sacerdotes!$F$90:$F$133,Sacerdotes!$H$90:$H$133,FALSE) -> 0 | AN43: =SUMIFS(Sacerdotes!$F$45:$F$87,Sacerdotes!$H$45:$H$87,FALSE) -> 0 | AO43: =SUMIFS(Sacerdotes!$F$3:$F$42,Sacerdotes!$H$3:$H$42,FALSE) -> 0
A44: Saldo Final | D44: =_xlfn.XLOOKUP($D$3,INDIRECT("$F$3:$AZ3" ),INDIRECT("$F" & ROW() & ":" & "$AZ" & ROW())) -> -6158.99 | F44: =F$42-F$43 -> -6158.99 | G44: =G$42-G$43 -> 6643.01 | H44: =H$42-H$43 -> 6249.68 | I44: =I$42-I$43 -> 2646.99 | J44: =J$42-J$43 -> 2155.39 | K44: =K$42-K$43 -> 1975.11 | L44: =L$42-L$43 -> 1810.62 | M44: =M$42-M$43 -> 6212.91 | ... AO44: =AO$42-AO$43 -> 1896.71

Sheet Dashboard
A1: Opção 1 | G1: Selecione o Ano | I1: 2026
B2: Resumo por Período | R2: Período | T2: Receitas | U2: Despesas | V2: Saldo | X2: Período | Z2: Coletas | AA2: Espórtulas | AB2: Saldo
B3: =R2 -> Período | C3: =T2 -> Receitas | D3: =U2 -> Despesas | E3: =V2 -> Saldo | R3: 2023 | S3: 45231 | T3: =Gerencial!$AO$6 -> 13368.55 | U3: =Gerencial!$AO$12 -> 11471.84 | V3: =Gerencial!$AO$42 -> 1896.71 | X3: 2023 | Y3: 45231 | Z3: =Gerencial!$AO$7 -> 12349 | AA3: =Gerencial!$AO$13 -> 5310 | AB3: =Z3-AA3 -> 7039
B4: =IFERROR(__xludf.DUMMYFUNCTION("FILTER($S$3:$V1002,YEAR($S$3:$S1002)=$I$1)"),46023.0) -> 46023 | C4: =IFERROR(__xludf.DUMMYFUNCTION("""COMPUTED_VALUE"""),12569.4) -> 12569.4 | D4: =IFERROR(__xludf.DUMMYFUNCTION("""COMPUTED_VALUE"""),13328.74) -> 13328.74 | E4: =IFERROR(__xludf.DUMMYFUNCTION("""COMPUTED_VALUE"""),4207.660000000009) -> 4207.66 | S4: 45261 | T4: =Gerencial!$AN$6 -> 10838.85 | U4: =Gerencial!$AN$12 -> 9674.37 | V4: =Gerencial!$AN$42 -> 3061.19 | Y4: 45261 | Z4: =Gerencial!$AN$7 -> 10392.6 | AA4: =Gerencial!$AN$13 -> 6720 | AB4: =Z4-AA4 -> 3672.6
B5: =IFERROR(__xludf.DUMMYFUNCTION("""COMPUTED_VALUE"""),46054.0) -> 46054 | C5: =IFERROR(__xludf.DUMMYFUNCTION("""COMPUTED_VALUE"""),12613.0) -> 12613 | D5: =IFERROR(__xludf.DUMMYFUNCTION("""COMPUTED_VALUE"""),11741.9) -> 11741.9 | E5: =IFERROR(__xludf.DUMMYFUNCTION("""COMPUTED_VALUE"""),5078.760000000011) -> 5078.76 | R5: 2024 | S5: 45292 | T5: =Gerencial!$AM$6 -> 9084.95 | U5: =Gerencial!$AM$12 -> 8932.05 | V5: =Gerencial!$AM$42 -> 3214.09 | X5: 2024 | Y5: 45292 | Z5: =Gerencial!$AM$7 -> 8517 | AA5: =Gerencial!$AM$13 -> 6210 | AB5: =Z5-AA5 -> 2307
B6: =IFERROR(__xludf.DUMMYFUNCTION("""COMPUTED_VALUE"""),46082.0) -> 46082 | C6: =IFERROR(__xludf.DUMMYFUNCTION("""COMPUTED_VALUE"""),13892.15) -> 13892.15 | D6: =IFERROR(__xludf.DUMMYFUNCTION("""COMPUTED_VALUE"""),12758.0) -> 12758 | E6: =IFERROR(__xludf.DUMMYFUNCTION("""COMPUTED_VALUE"""),6212.910000000011) -> 6212.91 | S6: 45323 | T6: =Gerencial!$AL$6 -> 7766.1 | U6: =Gerencial!$AL$12 -> 7973.87 | V6: =Gerencial!$AL$42 -> 3006.32 | Y6: 45323 | Z6: =Gerencial!$AL$7 -> 7390 | AA6: =Gerencial!$AL$13 -> 5600 | AB6: =Z6-AA6 -> 1790
B7: =IFERROR(__xludf.DUMMYFUNCTION("""COMPUTED_VALUE"""),46113.0) -> 46113 | C7: =IFERROR(__xludf.DUMMYFUNCTION("""COMPUTED_VALUE"""),10325.1) -> 10325.1 | D7: =IFERROR(__xludf.DUMMYFUNCTION("""COMPUTED_VALUE"""),14727.39) -> 14727.39 | E7: =IFERROR(__xludf.DUMMYFUNCTION("""COMPUTED_VALUE"""),1810.62000000001) -> 1810.62 | S7: 45352 | T7: =Gerencial!$AK$6 -> 12694.2 | U7: =Gerencial!$AK$12 -> 11251.34 | V7: =Gerencial!$AK$42 -> 4449.18 | Y7: 45352 | Z7: =Gerencial!$AK$7 -> 12294 | AA7: =Gerencial!$AK$13 -> 6900 | AB7: =Z7-AA7 -> 5394
B8: =IFERROR(__xludf.DUMMYFUNCTION("""COMPUTED_VALUE"""),46143.0) -> 46143 | C8: =IFERROR(__xludf.DUMMYFUNCTION("""COMPUTED_VALUE"""),13463.1) -> 13463.1 | D8: =IFERROR(__xludf.DUMMYFUNCTION("""COMPUTED_VALUE"""),13298.61) -> 13298.61 | E8: =IFERROR(__xludf.DUMMYFUNCTION("""COMPUTED_VALUE"""),1975.1100000000097) -> 1975.11 | S8: 45383 | T8: =Gerencial!$AJ$6 -> 9095.06 | U8: =Gerencial!$AJ$12 -> 9702.14 | V8: =Gerencial!$AJ$42 -> 3842.1 | Y8: 45383 | Z8: =Gerencial!$AJ$7 -> 8456 | AA8: =Gerencial!$AJ$13 -> 7200 | AB8: =Z8-AA8 -> 1256
B9: =IFERROR(__xludf.DUMMYFUNCTION("""COMPUTED_VALUE"""),46174.0) -> 46174 | C9: =IFERROR(__xludf.DUMMYFUNCTION("""COMPUTED_VALUE"""),14696.95) -> 14696.95 | D9: =IFERROR(__xludf.DUMMYFUNCTION("""COMPUTED_VALUE"""),14516.67) -> 14516.67 | E9: =IFERROR(__xludf.DUMMYFUNCTION("""COMPUTED_VALUE"""),2155.390000000012) -> 2155.39 | S9: 45413 | T9: =Gerencial!$AI$6 -> 9403.4 | U9: =Gerencial!$AI$12 -> 9819.12 | V9: =Gerencial!$AI$42 -> 3426.38 | Y9: 45413 | Z9: =Gerencial!$AI$7 -> 8933 | AA9: =Gerencial!$AI$13 -> 7400 | AB9: =Z9-AA9 -> 1533
B10: =IFERROR(__xludf.DUMMYFUNCTION("""COMPUTED_VALUE"""),46204.0) -> 46204 | C10: =IFERROR(__xludf.DUMMYFUNCTION("""COMPUTED_VALUE"""),14232.85) -> 14232.85 | D10: =IFERROR(__xludf.DUMMYFUNCTION("""COMPUTED_VALUE"""),13741.25) -> 13741.25 | E10: =IFERROR(__xludf.DUMMYFUNCTION("""COMPUTED_VALUE"""),2646.9900000000125) -> 2646.99 | S10: 45444 | T10: =Gerencial!$AH$6 -> 9515.95 | U10: =Gerencial!$AH$12 -> 10475.73 | V10: =Gerencial!$AH$42 -> 2466.6 | Y10: 45444 | Z10: =Gerencial!$AH$7 -> 9133 | AA10: =Gerencial!$AH$13 -> 7350 | AB10: =Z10-AA10 -> 1783
B11: =IFERROR(__xludf.DUMMYFUNCTION("""COMPUTED_VALUE"""),46235.0) -> 46235 | C11: =IFERROR(__xludf.DUMMYFUNCTION("""COMPUTED_VALUE"""),17512.0) -> 17512 | D11: =IFERROR(__xludf.DUMMYFUNCTION("""COMPUTED_VALUE"""),13909.31) -> 13909.31 | E11: =IFERROR(__xludf.DUMMYFUNCTION("""COMPUTED_VALUE"""),6249.680000000013) -> 6249.68 | S11: 45474 | T11: =Gerencial!$AG$6 -> 6929.7 | U11: =Gerencial!$AG$12 -> 8315.75 | V11: =Gerencial!$AG$42 -> 1080.55 | Y11: 45474 | Z11: =Gerencial!$AG$7 -> 6677 | AA11: =Gerencial!$AG$13 -> 7150 | AB11: =Z11-AA11 -> -473
B12: =IFERROR(__xludf.DUMMYFUNCTION("""COMPUTED_VALUE"""),46266.0) -> 46266 | C12: =IFERROR(__xludf.DUMMYFUNCTION("""COMPUTED_VALUE"""),13458.0) -> 13458 | D12: =IFERROR(__xludf.DUMMYFUNCTION("""COMPUTED_VALUE"""),13064.67) -> 13064.67 | E12: =IFERROR(__xludf.DUMMYFUNCTION("""COMPUTED_VALUE"""),6643.010000000015) -> 6643.01 | S12: 45505 | T12: =Gerencial!$AF$6 -> 8206.85 | U12: =Gerencial!$AF$12 -> 8155.99 | V12: =Gerencial!$AF$42 -> 1131.41 | Y12: 45505 | Z12: =Gerencial!$AF$7 -> 7955 | AA12: =Gerencial!$AF$13 -> 7007.2 | AB12: =Z12-AA12 -> 947.8
B13: =IFERROR(__xludf.DUMMYFUNCTION("""COMPUTED_VALUE"""),46296.0) -> 46296 | C13: =IFERROR(__xludf.DUMMYFUNCTION("""COMPUTED_VALUE"""),3058.0) -> 3058 | D13: =IFERROR(__xludf.DUMMYFUNCTION("""COMPUTED_VALUE"""),4310.0) -> 4310 | E13: =IFERROR(__xludf.DUMMYFUNCTION("""COMPUTED_VALUE"""),5391.010000000015) -> 5391.01 | S13: 45536 | T13: =Gerencial!$AE$6 -> 10311.25 | U13: =Gerencial!$AE$12 -> 8564.75 | V13: =Gerencial!$AE$42 -> 2877.91 | Y13: 45536 | Z13: =Gerencial!$AE$7 -> 9665 | AA13: =Gerencial!$AE$13 -> 6950 | AB13: =Z13-AA13 -> 2715
B14: =IFERROR(__xludf.DUMMYFUNCTION("""COMPUTED_VALUE"""),46327.0) -> 46327 | S14: 45566 | T14: =Gerencial!$AD$6 -> 9704.05 | U14: =Gerencial!$AD$12 -> 12451.86 | V14: =Gerencial!$AD$42 -> 130.1 | Y14: 45566 | Z14: =Gerencial!$AD$7 -> 9447 | AA14: =Gerencial!$AD$13 -> 7150 | AB14: =Z14-AA14 -> 2297
B15: =IFERROR(__xludf.DUMMYFUNCTION("""COMPUTED_VALUE"""),46357.0) -> 46357 | S15: 45597 | T15: =Gerencial!$AC$6 -> 11493.85 | U15: =Gerencial!$AC$12 -> 9428.78 | V15: =Gerencial!$AC$42 -> 2195.17 | Y15: 45597 | Z15: =Gerencial!$AC$7 -> 11075 | AA15: =Gerencial!$AC$13 -> 6850 | AB15: =Z15-AA15 -> 4225
B16: Total | C16: =SUM(C4:C15) -> 125820.55 | D16: =SUM(D4:D15) -> 125396.54 | E16: =C16-D16 -> 424.01 | S16: 45627 | T16: =Gerencial!$AB$6 -> 8900.35 | U16: =Gerencial!$AB$12 -> 8669.53 | V16: =Gerencial!$AB$42 -> 2425.99 | Y16: 45627 | Z16: =Gerencial!$AB$7 -> 8645 | AA16: =Gerencial!$AB$13 -> 6600 | AB16: =Z16-AA16 -> 2045
R17: 2025 | S17: 45658 | T17: =Gerencial!$AA$6 -> 7293.2 | U17: =Gerencial!$AA$12 -> 7458.12 | V17: =Gerencial!$AA$42 -> 2261.07 | X17: 2025 | Y17: 45658 | Z17: =Gerencial!$AA$7 -> 6989 | AA17: =Gerencial!$AA$13 -> 6900 | AB17: =Z17-AA17 -> 89
S18: 45689 | T18: =Gerencial!$Z$6 -> 7874 | U18: =Gerencial!$Z$12 -> 8622.88 | V18: =Gerencial!$Z$42 -> 1512.19 | Y18: 45689 | Z18: =Gerencial!$Z$7 -> 7615 | AA18: =Gerencial!$Z$13 -> 5900 | AB18: =Z18-AA18 -> 1715
B19: =Gerencial!D3 -> 2026/10 | S19: 45717 | T19: =Gerencial!$Y$6 -> 8835.45 | U19: =Gerencial!$Y$12 -> 7485.02 | V19: =Gerencial!$Y$42 -> 2862.62 | Y19: 45717 | Z19: =Gerencial!$Y$7 -> 8676 | AA19: =Gerencial!$Y$13 -> 6500 | AB19: =Z19-AA19 -> 2176
S20: 45748 | T20: =Gerencial!$X$6 -> 10935.7 | U20: =Gerencial!$X$12 -> 11055.31 | V20: =Gerencial!$X$42 -> 2743.01 | Y20: 45748 | Z20: =Gerencial!$X$7 -> 9178 | AA20: =Gerencial!$X$13 -> 7650 | AB20: =Z20-AA20 -> 1528
S21: 45778 | T21: =Gerencial!$W$6 -> 12050.35 | U21: =Gerencial!$W$12 -> 12750.15 | V21: =Gerencial!$W$42 -> 2043.21 | Y21: 45778 | Z21: =Gerencial!$W$7 -> 7668 | AA21: =Gerencial!$W$13 -> 11100 | AB21: =Z21-AA21 -> -3432
S22: 45809 | T22: =Gerencial!$V$6 -> 12309 | U22: =Gerencial!$V$12 -> 12427.72 | V22: =Gerencial!$V$42 -> 1924.49 | Y22: 45809 | Z22: =Gerencial!$V$7 -> 7662 | AA22: =Gerencial!$V$13 -> 10750 | AB22: =Z22-AA22 -> -3088
S23: 45839 | T23: =Gerencial!$U$6 -> 12602.15 | U23: =Gerencial!$U$12 -> 13318.58 | V23: =Gerencial!$U$42 -> 1208.06 | Y23: 45839 | Z23: =Gerencial!$U$7 -> 5258.75 | AA23: =Gerencial!$U$13 -> 11100 | AB23: =Z23-AA23 -> -5841.25
S24: 45870 | T24: =Gerencial!$T$6 -> 14058.75 | U24: =Gerencial!$T$12 -> 12759.19 | V24: =Gerencial!$T$42 -> 2507.62 | Y24: 45870 | Z24: =Gerencial!$T$7 -> 6496 | AA24: =Gerencial!$T$13 -> 10950 | AB24: =Z24-AA24 -> -4454
B25: DEMONSTRATIVO DO MÊS | S25: 45901 | T25: =Gerencial!$S$6 -> 15514.3 | U25: =Gerencial!$S$12 -> 12693.73 | V25: =Gerencial!$S$42 -> 5328.19 | Y25: 45901 | Z25: =Gerencial!$S$7 -> 6597 | AA25: =Gerencial!$S$13 -> 10950 | AB25: =Z25-AA25 -> -4353
S26: 45931 | T26: =Gerencial!$R$6 -> 13580.35 | U26: =Gerencial!$R$12 -> 15823.48 | V26: =Gerencial!$R$42 -> 3085.06 | Y26: 45931 | Z26: =Gerencial!$R$7 -> 9451 | AA26: =Gerencial!$R$13 -> 11650 | AB26: =Z26-AA26 -> -2199
S27: 45962 | T27: =Gerencial!$Q$6 -> 14452 | U27: =Gerencial!$Q$12 -> 11820.5 | V27: =Gerencial!$Q$42 -> 5716.56 | Y27: 45962 | Z27: =Gerencial!$Q$7 -> 8539 | AA27: =Gerencial!$Q$13 -> 10650 | AB27: =Z27-AA27 -> -2111
S28: 45992 | T28: =Gerencial!$P$6 -> 14926.45 | U28: =Gerencial!$P$12 -> 15676.01 | V28: =Gerencial!$P$42 -> 4967 | Y28: 45992 | Z28: =Gerencial!$P$7 -> 9311 | AA28: =Gerencial!$P$13 -> 11050 | AB28: =Z28-AA28 -> -1739
R29: 2026 | S29: 46023 | T29: =Gerencial!$O$6 -> 12569.4 | U29: =Gerencial!$O$12 -> 13328.74 | V29: =Gerencial!$O$42 -> 4207.66 | X29: 2026 | Y29: 46023 | Z29: =Gerencial!$O$7 -> 7269 | AA29: =Gerencial!$O$13 -> 11200 | AB29: =Z29-AA29 -> -3931
S30: 46054 | T30: =Gerencial!$N$6 -> 12613 | U30: =Gerencial!$N$12 -> 11741.9 | V30: =Gerencial!$N$42 -> 5078.76 | Y30: 46054 | Z30: =Gerencial!$N$7 -> 8925 | AA30: =Gerencial!$N$13 -> 10100 | AB30: =Z30-AA30 -> -1175
S31: 46082 | T31: =Gerencial!$M$6 -> 13892.15 | U31: =Gerencial!$M$12 -> 12758 | V31: =Gerencial!$M$42 -> 6212.91 | Y31: 46082 | Z31: =Gerencial!$M$7 -> 10389.35 | AA31: =Gerencial!$M$13 -> 11400 | AB31: =Z31-AA31 -> -1010.65
S32: 46113 | T32: =Gerencial!$L$6 -> 10325.1 | U32: =Gerencial!$L$12 -> 14727.39 | V32: =Gerencial!$L$42 -> 1810.62 | Y32: 46113 | Z32: =Gerencial!$L$7 -> 10139 | AA32: =Gerencial!$L$13 -> 10350 | AB32: =Z32-AA32 -> -211
S33: 46143 | T33: =Gerencial!$K$6 -> 13463.1 | U33: =Gerencial!$K$12 -> 13298.61 | V33: =Gerencial!$K$42 -> 1975.11 | Y33: 46143 | Z33: =Gerencial!$K$7 -> 10083.25 | AA33: =Gerencial!$K$13 -> 11400 | AB33: =Z33-AA33 -> -1316.75
S34: 46174 | T34: =Gerencial!$J$6 -> 14696.95 | U34: =Gerencial!$J$12 -> 14516.67 | V34: =Gerencial!$J$42 -> 2155.39 | Y34: 46174 | Z34: =Gerencial!$J$7 -> 9348 | AA34: =Gerencial!$J$13 -> 11000 | AB34: =Z34-AA34 -> -1652
S35: 46204 | T35: =Gerencial!$I$6 -> 14232.85 | U35: =Gerencial!$I$12 -> 13741.25 | V35: =Gerencial!$I$42 -> 2646.99 | Y35: 46204 | Z35: =Gerencial!$I$7 -> 8038 | AA35: =Gerencial!$I$13 -> 11800 | AB35: =Z35-AA35 -> -3762
S36: 46235 | T36: =Gerencial!$H$6 -> 17512 | U36: =Gerencial!$H$12 -> 13909.31 | V36: =Gerencial!$H$42 -> 6249.68 | Y36: 46235
S37: 46266 | T37: =Gerencial!$G$6 -> 13458 | U37: =Gerencial!$G$12 -> 13064.67 | V37: =Gerencial!$G$42 -> 6643.01 | Y37: 46266
S38: 46296 | T38: =Gerencial!$F$6 -> 3058 | U38: =Gerencial!$F$12 -> 4310 | V38: =Gerencial!$F$42 -> 5391.01 | Y38: 46296
S39: 46327 | Y39: 46327
S40: 46357 | Y40: 46357
...

Sheet Entradas
A2: COLETAS | I2: INTENÇÕES | N2: EMPRÉSTIMOS
A3: Data | B3: Dia | C3: Turno | D3: Celebrante | E3: Valor coleta | F3: Responsáveis | G3: Observação | I3: Data | J3: Dia da semana | K3: Valor | L3: Observação | N3: Data | O3: Dia da semana | P3: Valor | Q3: Observação
A4: 45231 | B4: =A4 -> 45231 | C4: Manhã | D4: Monsenhor Idelfonso | E4: 145 | F4: Oscar e Milena | I4: 45233 | J4: =I4 -> 45233 | K4: 98.65 | N4: 45231 | O4: Quarta-feira | P4: 700 | Q4: Nilda pgto espórtulas dias 3 e 5
A5: 45232 | B5: =A5 -> 45232 | C5: Manhã | D5: Monsenhor Idelfonso | E5: 665 | F5: Wilson e Aucilene | I5: 45238 | J5: =I5 -> 45238 | K5: 17.7 | O5: =N5
A6: 45233 | B6: =A6 -> 45233 | C6: Manhã | D6: Padre Marcos | E6: 200 | F6: João Paulo e Neide | I6: 45244 | J6: =I6 -> 45244 | K6: 37.6 | O6: =N6
C7: Noite | D7: Padre Josieldo | E7: 257 | F7: Vieira e Wandson | G7: Missa das famílias | I7: 45245 | J7: =I7 -> 45245 | K7: 42.1 | O7: =N7
A8: 45235 | B8: =A8 -> 45235 | C8: Manhã | D8: Padre Josieldo | E8: 650 | F8: Wandson e Ailton | I8: 45254 | J8: =I8 -> 45254 | K8: 38
A9: 45235 | B9: =A9 -> 45235 | C9: Noite | D9: Padre Pafael Maciel | E9: 674 | F9: Ana Lúcia e Alberto | I9: 45256 | J9: =I9 -> 45256 | K9: 39
A10: 45236 | B10: =A10 -> 45236 | C10: Manhã | D10: Monsenhor Idelfonso | E10: 52 | F10: Ana Lúcia e Oscar | I10: 45259 | J10: =I10 -> 45259 | K10: 46.5
A11: 45237 | B11: =A11 -> 45237 | C11: Manhã | D11: Padre Marcos | E11: 185 | F11: Vieira e Clediana
A12: 45238 | B12: =A12 -> 45238 | C12: Manhã | D12: Monsenhor Idelfonso | E12: 155 | F12: Neide e Tânia
A13: 45239 | B13: =A13 -> 45239 | C13: Manhã | D13: Monsenhor Idelfonso | E13: 91 | F13: Sávio e Albaniza
A14: 45240 | B14: =A14 -> 45240 | C14: Manhã | D14: Padre Josieldo | E14: 113 | F14: João Paulo e Neide
A15: 10 | B15: sexta-feira | C15: Noite | D15: Padre Virgínio | E15: 2750 | F15: Milena, Ailton, Liliane, Eduardo, Adaila | G15: Missa da Crisma
A16: 11 | B16: sábado | C16: Noite | D16: Padre Santino Sacramento | E16: 669 | F16: Oscar, Vieira, Albaniza | G16: Missa da Catequese
A17: 45242 | B17: =A17 -> 45242 | C17: Manhã | D17: Padre Josieldo | E17: 620 | F17: Wilson Camelo e Eduardo
C18: Noite | D18: Padre Watson | E18: 650 | F18: Wandson e Lidia
A19: 45243 | B19: =A19 -> 45243 | C19: Manhã | D19: Monsenhor Idelfonso | E19: 200 | F19: Ana Lúcia e Alaide
A20: 45244 | B20: =A20 -> 45244 | C20: Manhã | D20: Marcos | E20: 90 | F20: Clediana e Tânia
A21: 45245 | B21: =A21 -> 45245 | C21: Manhã | D21: Monsenhor Idelfonso | E21: 239 | F21: Vieira e Myrtes
A22: 45246 | B22: =A22 -> 45246 | C22: Manhã | D22: Monsenhor Idelfonso | E22: 118 | F22: Ailton e Milena
A23: 45247 | B23: =A23 -> 45247 | C23: Manhã | D23: Padre Josieldo | E23: 90 | F23: João Paulo e Alda
A24: 45248 | B24: =A24 -> 45248 | C24: Manhã | D24: N/A | E24: 0 | F24: N/A | I24: Total | K24: =SUM(K4:K23) -> 319.55 | N24: Total | P24: =SUM(P4:P23) -> 700
A25: 45249 | B25: =A25 -> 45249 | C25: Manhã | D25: Padre Josieldo | E25: 610 | F25: Marquinhos
C26: Noite | D26: Padre Paulo | E26: 920 | F26: Jarbas e Eduardo
A27: 45250 | B27: =A27 -> 45250 | C27: Manhã | D27: Monsenhor Idelfonso | E27: 113 | F27: Ana Lucia e Alaide
A28: 45251 | B28: =A28 -> 45251 | C28: Manhã | E28: 70 | F28: Clediana e Alda
A29: 45252 | B29: =A29 -> 45252 | C29: Manhã | D29: Monsenhor Idelfonso | E29: 134 | F29: Sávio e Tânia
A30: 45253 | B30: =A30 -> 45253 | C30: Manhã | D30: Monsenhor Idelfonso | E30: 47 | F30: Sávio e Milena
A31: 45254 | B31: =A31 -> 45254 | C31: Manhã | D31: Padre Josieldo | E31: 61 | F31: João Paulo e Tânia
A32: 45255 | B32: =A32 -> 45255 | C32: Manhã | D32: Padre Diego Juaçaba | E32: 120 | F32: Pe Diego Juaçaba | G32: Missa Célia Nóbrega
A33: 45256 | B33: =A33 -> 45256 | C33: Manhã | D33: Frei Ricardo Régis | E33: 594 | F33: Neidinha e Vieira
C34: Noite | D34: Padre Diego Juaçaba | E34: 664 | F34: Lena e Eduardo
A35: 45257 | B35: =A35 -> 45257 | C35: Manhã | D35: Monsenhor Idelfonso | E35: 55 | F35: Ana Lúcia e Alaide
A36: 45258 | B36: =A36 -> 45258 | C36: Manhã | D36: Monsenhor Idelfonso | E36: 120 | F36: Clediana e Sávio
A37: 45259 | B37: =A37 -> 45259 | C37: Manhã | D37: Padre Diego Juaçaba | E37: 107 | F37: Ailton e Liliane
A38: 45260 | B38: =A38 -> 45260 | C38: Manhã | D38: Padre Diego Juaçaba | E38: 121 | F38: Vieira e Ana Lúcia
A39: Total | E39: =SUM(E4:E38) -> 12349
A41: Dezembro/2023
A42: COLETAS | I42: INTENÇÕES | N42: EMPRÉSTIMOS
...

Sheet Despesas
A1: x | B1: Data | C1: Descrição | D1: Qtde | E1: Vlr. Unit | F1: Valor | G1: Valor Doc | H1: Padres | I1: Fornecedor | J1: Observação | K1: Nota | L1: Recibo | M1: Tapete
A2: Novembro/2023
A3: 2023/11 | B3: 45231 | C3: Velas ( Altar, Santíssimo e diárias ) | D3: 4 | E3: 18.9 | F3: 75.6 | G3: 75.6 | H3: FALSE | I3: Renna Luz | J3: Velas 15 x 7 - Coroa do Advento. Recibo 30/10
A4: 2023/11 | B4: 45231 | C4: Carvão Tablete | D4: 3 | E4: 10 | F4: 30 | G4: 30 | H4: FALSE | I4: Casa de Maria | J4: Carvão
A5: 2023/11 | B5: 45233 | C5: Espórtulas | D5: 1 | E5: 150 | F5: 150 | G5: 150 | H5: TRUE | I5: Padre Marcos | J5: Missa manhã
A6: 2023/11 | B6: 45233 | C6: Espórtulas | D6: 1 | E6: 150 | F6: 150 | G6: 150 | H6: TRUE | I6: Padre Josieldo | J6: Missa das Famílias
A7: 2023/11 | B7: 45233 | C7: Velas ( Altar, Santíssimo e diárias ) | D7: 13 | E7: 17.01 | F7: 221.13 | G7: 221.13 | H7: FALSE | I7: Renna Luz | J7: Velas 15 x 7 Brancas
A8: 2023/11 | B8: 45235 | C8: Espórtulas | D8: 1 | E8: 200 | F8: 200 | G8: 200 | H8: TRUE | I8: Padre Josieldo | J8: Missa manhã
A9: 2023/11 | B9: 45235 | C9: Espórtulas | D9: 1 | E9: 200 | F9: 200 | G9: 200 | H9: TRUE | I9: Padre Raphael | J9: Missa noite
A10: 2023/11 | B10: 45236 | C10: Papel toalha | D10: 2 | E10: 6.29 | F10: =D10*E10 -> 12.58 | G10: =SUM(F10:F12) -> 21.46 | H10: FALSE | I10: Center Box
A11: 2023/11 | B11: 45236 | C11: Água Sanitária | D11: 1 | E11: 1.59 | F11: =D11*E11 -> 1.59
A12: 2023/11 | B12: 45236 | C12: Cheirinho ( anti-môfo) | D12: 1 | E12: 7.29 | F12: =D12*E12 -> 7.29
A13: 2023/11 | B13: 45236 | C13: Partículas | D13: 3 | E13: 35 | F13: =D13*E13 -> 105 | G13: =SUM(F13:F15) -> 175 | H13: FALSE | I13: Mosteiro da Imaculada Conceição e São José | J13: hóstias pequenas. Pct com 1k
A14: 2023/11 | B14: 45236 | C14: Partículas | D14: 1 | E14: 35 | F14: =D14*E14 -> 35 | J14: Hóstias 10 cm. pct com 10 und
A15: 2023/11 | B15: 45236 | C15: Partículas | D15: 1 | E15: 35 | F15: =D15*E15 -> 35 | J15: Hóstias 14 cm. pct com 10 und
A16: 2023/11 | B16: 45236 | C16: Água | D16: 1 | E16: 12 | F16: 12 | G16: 12 | H16: FALSE | I16: Posto Caribe | J16: Garrafão 20 lts indaiá
A17: 2023/11 | B17: 45237 | C17: Espórtulas | D17: 1 | E17: 150 | F17: 150 | G17: 150 | H17: TRUE | I17: Padre Marcos | J17: Missa 07/11 - manhã
A18: 2023/11 | B18: 45237 | C18: Alcóol | D18: 2 | E18: 8.69 | F18: =E18*D18 -> 17.38 | G18: =F18 -> 17.38 | H18: FALSE | I18: Frangolândia | J18: Alcóol
A19: 2023/11 | B19: 45238 | C19: Devolução de Empréstimos | D19: 1 | E19: 700 | F19: 700 | G19: 700 | H19: FALSE | J19: Valor usado para pgto de espórtulas dos dias 3 e 5
A20: 2023/11 | B20: 45240 | C20: Espórtulas | D20: 1 | E20: 150 | F20: 150 | G20: 150 | H20: TRUE | I20: Padre Josieldo | J20: Missa sexta - 10/11 - manhã
A21: 2023/11 | B21: 45240 | C21: Velas ( Altar, Santíssimo e diárias ) | D21: 3 | E21: 7.7 | F21: =D21*E21 -> 23.1 | G21: 23.1 | H21: FALSE | I21: Renna Luz | J21: Velas cast lisa (par)
A22: 2023/11 | B22: 45240 | C22: Lavanderia | D22: 1 | E22: 116 | F22: =D22*E22 -> 116 | G22: 116 | H22: FALSE | I22: Lavanderia Lig-Lave | J22: Túnicas dos padres
A23: 2023/11 | B23: 45241 | C23: Outros | D23: 1 | E23: 80 | F23: 80 | G23: 80 | H23: FALSE | I23: Chaveiro | J23: Fechadura armário sacristia
A24: 2023/11 | B24: 45242 | C24: Espórtulas | D24: 1 | E24: 200 | F24: 200 | G24: 200 | H24: TRUE | I24: Padre Josieldo | J24: Missa domingo 10/11 - manhã
A25: 2023/11 | B25: 45242 | C25: Espórtulas | D25: 1 | E25: 200 | F25: 200 | G25: 200 | H25: TRUE | I25: Padre Watson | J25: Missa domingo 10/11 - noite
A26: 2023/11 | B26: 45244 | C26: Espórtulas | D26: 1 | E26: 150 | F26: 150 | G26: 150 | H26: TRUE | I26: Padre Marcos | J26: Missa terça-feira 14/11 manhã
A27: 2023/11 | B27: 45244 | C27: Produtos de limpeza | D27: 1 | E27: 48.1 | F27: 48.1 | G27: 48.1 | H27: FALSE | I27: Distrilimp ind. com... | J27: Limpeza do banheiro da sacristia
A28: 2023/11 | B28: 45245 | C28: Descartáveis (Copos, pratos) | D28: 4 | E28: 2.19 | F28: =D28*E28 -> 8.76 | G28: =SUM(F28:F38) -> 125.94 | H28: FALSE | I28: Centerbox | J28: Partos descartáveis
A29: 2023/11 | B29: 45245 | C29: Fraternidade | Aniversariantes | D29: 2 | E29: 2.29 | F29: =D29*E29 -> 4.58 | J29: Guardanapos
A30: 2023/11 | B30: 45245 | C30: Fraternidade | Aniversariantes | D30: 1 | E30: 1.39 | F30: =D30*E30 -> 1.39 | J30: Palitos de dente
A31: 2023/11 | B31: 45245 | C31: Fraternidade | Aniversariantes | D31: 1 | E31: 5.99 | F31: =D31*E31 -> 5.99 | J31: Vela vulcão
A32: 2023/11 | B32: 45245 | C32: Produtos de limpeza | D32: 1 | E32: 5.99 | F32: =D32*E32 -> 5.99 | J32: Multiuso Veja
A33: 2023/11 | B33: 45245 | C33: Produtos de limpeza | D33: 1 | E33: 5.99 | F33: =D33*E33 -> 5.99 | J33: Lustra móveis
A34: 2023/11 | B34: 45245 | C34: Produtos de limpeza | D34: 1 | E34: 7.99 | F34: =D34*E34 -> 7.99 | J34: Esponja
A35: 2023/11 | B35: 45245 | C35: Produtos de limpeza | D35: 1 | E35: 2.39 | F35: =D35*E35 -> 2.39 | J35: Detergente líquido
A36: 2023/11 | B36: 45245 | C36: Produtos de limpeza | D36: 1 | E36: 13.99 | F36: =D36*E36 -> 13.99 | J36: Desinfetante kalipto
A37: 2023/11 | B37: 45245 | C37: Produtos de limpeza | D37: 2 | E37: 4.44 | F37: =D37*E37 -> 8.88 | J37: Pedra sanitário
A38: 2023/11 | B38: 45245 | C38: Produtos de limpeza | D38: 1 | E38: 59.99 | F38: =D38*E38 -> 59.99 | J38: Polidor silvo 2ooml
A39: 2023/11 | B39: 45247 | C39: Espórtulas | D39: 1 | E39: 150 | F39: 150 | G39: 150 | H39: TRUE | I39: Padre Josieldo | J39: Missa sexta-feira 17/11 - manhã
A40: 2023/11 | B40: 45249 | C40: Espórtulas | D40: 1 | E40: 200 | F40: 200 | G40: 200 | H40: TRUE | I40: Padre Josieldo | J40: Missa domingo 19/11 - manhã
...

Sheet Sacerdotes
A1: Dia | B1: Dia da semana | C1: Turno | D1: Sacerdote | E1: Descrição | F1: Valor | G1: Observação | H1: Pago
A2: Novembro/2023
A3: 45231 | B3: =A3 -> 45231 | C3: Manhã | D3: Idelfonso | E3: Missa | F3: 130 | H3: TRUE
A4: 45232 | B4: =A4 -> 45232 | C4: Manhã | D4: Idelfonso | E4: Missa | F4: 130 | H4: TRUE
A5: 45233 | B5: =A5 -> 45233 | C5: Manhã | D5: Marcos | E5: Missa | F5: 150 | H5: TRUE
D6: Idelfonso | E6: Missa | F6: 130 | H6: TRUE | K6: Resumo do mês NOV/2023 - Espórtulas
C7: Noite | D7: Josieldo | E7: Missa | F7: 150 | G7: Missa das famílias | H7: TRUE | K7: Sacerdote | L7: Missa | M7: Confissão | N7: Total | O7: Total Previsto | P7: Total Realizado | Q7: Saldo a Pagar
A8: 45235 | B8: =A8 -> 45235 | C8: Manhã | D8: Josieldo | E8: Missa | F8: 200 | H8: TRUE | K8: Josieldo | L8: =COUNTIFS($D$3:$D$42, $K8,$E$3:$E$42,$L$7) -> 7 | M8: =COUNTIFS($D$3:$D$42, $K8,$E$3:$E$42,$M$7) -> 0 | N8: =L8+M8 -> 7 | O8: =SUMIFS($F$3:$F$42,$D$3:$D$42,$K8) -> 1250 | P8: =SUMIFS($F$3:$F$42,$D$3:$D$42,$K8,$H$3:$H$42,TRUE) -> 1250 | Q8: =O8-P8 -> 0
C9: Noite | D9: Raphael | E9: Missa | F9: 200 | H9: TRUE | K9: Marcos | L9: =COUNTIFS($D$3:$D$42, $K9,$E$3:$E$42,$L$7) -> 6 | M9: =COUNTIFS($D$3:$D$42, $K9,$E$3:$E$42,$M$7) -> 0 | N9: =L9+M9 -> 6 | O9: =SUMIFS($F$3:$F$42,$D$3:$D$42,$K9) -> 600 | P9: =SUMIFS($F$3:$F$42,$D$3:$D$42,$K9,$H$3:$H$42,TRUE) -> 600 | Q9: =O9-P9 -> 0
A10: 45236 | B10: =A10 -> 45236 | C10: Manhã | D10: Idelfonso | E10: Missa | F10: 130 | H10: TRUE | K10: Idelfonso | L10: =COUNTIFS($D$3:$D$42, $K10,$E$3:$E$42,$L$7) -> 15 | M10: =COUNTIFS($D$3:$D$42, $K10,$E$3:$E$42,$M$7) -> 6 | N10: =L10+M10 -> 21 | O10: =SUMIFS($F$3:$F$42,$D$3:$D$42,$K10) -> 2730 | P10: =SUMIFS($F$3:$F$42,$D$3:$D$42,$K10,$H$3:$H$42,TRUE) -> 2730 | Q10: =O10-P10 -> 0
A11: 45237 | B11: =A11 -> 45237 | C11: Manhã | D11: Marcos | E11: Missa | F11: 150 | H11: TRUE | K11: Raphael | L11: =COUNTIFS($D$3:$D$42, $K11,$E$3:$E$42,$L$7) -> 1 | M11: =COUNTIFS($D$3:$D$42, $K11,$E$3:$E$42,$M$7) -> 0 | N11: =L11+M11 -> 1 | O11: =SUMIFS($F$3:$F$42,$D$3:$D$42,$K11) -> 200 | P11: =SUMIFS($F$3:$F$42,$D$3:$D$42,$K11,$H$3:$H$42,TRUE) -> 200 | Q11: =O11-P11 -> 0
C12: Manhã | D12: Idelfonso | E12: Confissão | F12: 130 | H12: TRUE | K12: Watson | L12: =COUNTIFS($D$3:$D$42, $K12,$E$3:$E$42,$L$7) -> 1 | M12: =COUNTIFS($D$3:$D$42, $K12,$E$3:$E$42,$M$7) -> 0 | N12: =L12+M12 -> 1 | O12: =SUMIFS($F$3:$F$42,$D$3:$D$42,$K12) -> 200 | P12: =SUMIFS($F$3:$F$42,$D$3:$D$42,$K12,$H$3:$H$42,TRUE) -> 200 | Q12: =O12-P12 -> 0
A13: 45238 | B13: =A13 -> 45238 | C13: Manhã | D13: Idelfonso | E13: Missa | F13: 130 | H13: TRUE | K13: Paulo Aniceto | L13: =COUNTIFS($D$3:$D$42, $K13,$E$3:$E$42,$L$7) -> 1 | M13: =COUNTIFS($D$3:$D$42, $K13,$E$3:$E$42,$M$7) -> 0 | N13: =L13+M13 -> 1 | O13: =SUMIFS($F$3:$F$42,$D$3:$D$42,$K13) -> 200 | P13: =SUMIFS($F$3:$F$42,$D$3:$D$42,$K13,$H$3:$H$42,TRUE) -> 200 | Q13: =O13-P13 -> 0
A14: 45239 | B14: =A14 -> 45239 | C14: Manhã | D14: Idelfonso | E14: Missa | F14: 130 | H14: TRUE | K14: Diego Juaçaba | L14: =COUNTIFS($D$3:$D$42, $K14,$E$3:$E$42,$L$7) -> 3 | M14: =COUNTIFS($D$3:$D$42, $K14,$E$3:$E$42,$M$7) -> 0 | N14: =L14+M14 -> 3 | O14: =SUMIFS($F$3:$F$42,$D$3:$D$42,$K14) -> 130 | P14: =SUMIFS($F$3:$F$42,$D$3:$D$42,$K14,$H$3:$H$42,TRUE) -> 130 | Q14: =O14-P14 -> 0
A15: 45240 | B15: =A15 -> 45240 | C15: Manhã | D15: Josieldo | E15: Missa | F15: 150 | H15: TRUE
D16: Idelfonso | E16: Confissão | F16: 130 | H16: TRUE
A17: 45242 | B17: =A17 -> 45242 | C17: Manhã | D17: Josieldo | E17: Missa | F17: 200 | H17: TRUE
C18: Noite | D18: Watson | E18: Missa | F18: 200 | H18: TRUE
A19: 45243 | B19: =A19 -> 45243 | C19: Manhã | D19: Idelfonso | E19: Missa | F19: 130 | H19: TRUE
A20: 45244 | B20: =A20 -> 45244 | C20: Manhã | D20: Marcos | E20: Missa | F20: 150 | H20: TRUE
D21: Idelfonso | E21: Confissão | F21: 130 | H21: TRUE
A22: 45245 | B22: =A22 -> 45245 | C22: Manhã | D22: Idelfonso | E22: Missa | F22: 130 | H22: TRUE
A23: 45246 | B23: =A23 -> 45246 | C23: Manhã | D23: Idelfonso | E23: Missa | F23: 130 | H23: TRUE | K23: Total | L23: =SUM(L8:L22) -> 34 | M23: =SUM(M8:M22) -> 6 | N23: =SUM(N8:N22) -> 40 | O23: =SUM(O8:O22) -> 5310 | P23: =SUM(P8:P22) -> 5310 | Q23: =SUM(Q8:Q22) -> 0
A24: 45247 | B24: =A24 -> 45247 | C24: Manhã | D24: Josieldo | E24: Missa | F24: 150 | H24: TRUE
C25: Manhã | D25: Idelfonso | E25: Confissão | F25: 130 | H25: TRUE
A26: 45249 | B26: =A26 -> 45249 | C26: Manhã | D26: Josieldo | E26: Missa | F26: 200 | H26: TRUE
C27: Noite | D27: Paulo Aniceto | E27: Missa | F27: 200 | H27: TRUE
A28: 45250 | B28: =A28 -> 45250 | C28: Manhã | D28: Idelfonso | E28: Missa | F28: 130 | H28: TRUE
A29: 45251 | B29: =A29 -> 45251 | C29: Manhã | D29: Marcos | E29: Missa | F29: 0 | G29: Pe Marcos não pôde celebrar | H29: FALSE
D30: Idelfonso | E30: Missa | F30: 130 | H30: TRUE
A31: 45252 | B31: =A31 -> 45252 | C31: Manhã | D31: Idelfonso | E31: Missa | F31: 130 | H31: TRUE
A32: 45253 | B32: =A32 -> 45253 | C32: Manhã | D32: Idelfonso | E32: Missa | F32: 130 | H32: TRUE
A33: 45254 | B33: =A33 -> 45254 | C33: Manhã | D33: Marcos | E33: Missa | F33: 150 | H33: TRUE
D34: Idelfonso | E34: Confissão | F34: 130 | H34: TRUE
A35: 45256 | B35: =A35 -> 45256 | C35: Manhã | D35: Josieldo | E35: Missa | F35: 200 | H35: TRUE
C36: Noite | D36: Diego Juaçaba | E36: Missa | F36: 0 | G36: Não aceitou a espórtula | H36: FALSE
A37: 45257 | B37: =A37 -> 45257 | C37: Manhã | D37: Idelfonso | E37: Missa | F37: 130 | H37: TRUE
A38: 45258 | B38: =A38 -> 45258 | C38: Manhã | D38: Marcos | E38: Missa | F38: 0 | G38: Pe Marcos não pôde celebrar | H38: FALSE
D39: Idelfonso | E39: Missa | F39: 130 | H39: TRUE
A40: 45259 | B40: =A40 -> 45259 | C40: Manhã | D40: Diego Juaçaba | E40: Missa | F40: 0 | G40: Não aceitou a espórtula | H40: FALSE
...

Sheet Limpeza
A1: aqui
A2: Abril/2026
A3: 46119 | B3: =A3 -> 46119 | C3: Maria José Marinho | D3: 170 | E3: TRUE | G3: Valor Pago
A4: 46121 | B4: =A4 -> 46121 | C4: Maria José Marinho | D4: 170 | E4: TRUE | G4: =SUMIF($E$1:$E$10, TRUE, $D$1:$D$10) -> 1360
A5: 46126 | B5: =A5 -> 46126 | C5: Maria José Marinho | D5: 170 | E5: TRUE
A6: 46128 | B6: =A6 -> 46128 | C6: Maria José Marinho | D6: 170 | E6: TRUE
A7: 46134 | B7: =A7 -> 46134 | C7: Maria José Marinho | D7: 170 | E7: TRUE | G7: Valor a Pagar
A8: 46135 | B8: =A8 -> 46135 | C8: Maria José Marinho | D8: 170 | E8: TRUE | G8: =D11-G4 -> 0
A9: 46140 | B9: =A9 -> 46140 | C9: Maria José Marinho | D9: 170 | E9: TRUE
A10: 46142 | B10: =A10 -> 46142 | C10: Maria José Marinho | D10: 170 | E10: TRUE
A11: Total | D11: =SUM(D3:D10) -> 1360
A13: Maio/2026
A14: 46147 | B14: =A14 -> 46147 | C14: Maria José Marinho | D14: 0 | E14: TRUE | F14: AUSENTE | G14: Valor Pago
A15: 46150 | B15: =A15 -> 46150 | C15: Maria José Marinho | D15: 170 | E15: TRUE | G15: =SUMIF($E$14:$E$21, TRUE, $D$14:$D$21) -> 1020
A16: 46155 | B16: =A16 -> 46155 | C16: Maria José Marinho | D16: 170 | E16: TRUE
A17: 46157 | B17: =A17 -> 46157 | C17: Maria José Marinho | D17: 170 | E17: TRUE
A18: 46162 | B18: =A18 -> 46162 | C18: Maria José Marinho | D18: 170 | E18: TRUE | G18: Valor a Pagar
A19: 46164 | B19: =A19 -> 46164 | C19: Maria José Marinho | D19: 170 | E19: TRUE | G19: =D22-G15 -> 170
A20: 46169 | B20: =A20 -> 46169 | C20: Maria José Marinho | D20: 170 | E20: TRUE
A21: 46170 | B21: =A21 -> 46170 | C21: Maria José Marinho | D21: 170 | E21: FALSE
A22: Total | D22: =SUM(D14:D21) -> 1190

Sheet Tabelas Básicas
A1: Itens de Consumo | E1: Sacerdotes | H1: Serviços | J1: Fornecedores
A2: Item | B2: Descrição | E2: André | H2: Missa | J2: Material | K2: Nome | L2: Endereço | M2: Bairro | N2: Fone | O2: Contato | P2: Observação
A3: 1 | B3: Bloco de recibos | E3: Arthur Ricardo | H3: Confissão | J3: Carvão (Tablete) | K3: Lojas Paulinas | L3: Av. Antonio Sales, 2919 | M3: Dionisio Torres | N3: (85) 998570146
A4: 2 | B4: Vinho | E4: Bessa | H4: Formação | J4: Vinho canônico | K4: Lojas Paulinas | L4: Av. Antonio Sales, 2919 | M4: Dionisio Torres | N4: (85) 998570146
A5: 3 | B5: Partículas | E5: Cosmo | H5: Diácono | J5: Diretório Litúrgico | K5: Lojas Paulinas | L5: Av. Antonio Sales, 2919 | M5: Dionisio Torres | N5: (85) 998570146
A6: 4 | B6: Água | E6: Deusimar | J6: Partículas Litúrgicas | K6: Mosteiro N.S. da Conceição | L6: Rua. Visconde do Rio Branco, 2590 | N6: (85) 32262038
A7: 5 | B7: Copos descartáveis ( 180 ml ) | E7: Diego Félix | J7: Vinho canônico | K7: Instituto das Filhas de São José | L7: Av. da Universidade, 3186 | M7: Damas | N7: (85) 3281.5135
A8: 6 | B8: Papel toalha | E8: Diego Juaçaba | H8: Anos | J8: Manga de vidro | K8: Lojas Vozes
A9: 7 | B9: Cheirinho ( anti-môfo) | E9: Douglas | H9: 2023 | J9: Manga de vidro | K9: Lojas Paulinas | L9: Av. Antonio Sales, 2919 | M9: Dionisio Torres | N9: (85) 998570146
